<?xml version="1.0" encoding="UTF-8"?>
<root xmlns:xacro="http://ros.org/wiki/xacro">


    <xacro:macro name="express_link" params="link_name">
        <link name="${link_name}">
            <inertial>
                <mass value="10.0" />
                <inertia ixx="1.857343821996639" ixy="6.2983660131078E-05" ixz="-3.19177822902163E-05" iyy="2.9174970781523" iyz="-8.19713905978223E-05" izz="1.76131215859239" />
            </inertial>
            <visual>
                <origin xyz="0 0 0" rpy="0 0 0" />
                <geometry>
                    <mesh filename="package://mantis_on_rack/meshes/Express_Rack.dae" />
                </geometry>
            </visual>
<!--
            <collision>
                <origin xyz="0 0 0" rpy="0 0 0" />
                <geometry>
                    <mesh filename="package://mantis_on_rack/meshes/Express_Rack.dae" />
                </geometry>
            </collision> -->
        </link>

        <link name="merlin_door">
            <inertial>
                <mass value="1.0" />
                <inertia ixx="0.857343821996639" ixy="6.2983660131078E-05" ixz="-3.19177822902163E-05" iyy="0.9174970781523" iyz="-8.19713905978223E-05" izz="0.76131215859239" />
            </inertial>
            <visual>
                <origin xyz="0 0 0" rpy="0 0 0" />
                <geometry>
                    <mesh filename="package://mantis_on_rack/meshes/merlin_door.dae" />
                </geometry>
            </visual>
            <!-- collision>
                <origin xyz="0 0 0" rpy="0 0 0" />
                <geometry>
                    <mesh filename="package://mantis_on_rack/meshes/merlin_door.dae" />
                </geometry>
            </collision -->
        </link>
        <gazebo reference="merlin_door">
            <material>
                Gazebo/Green
            </material>
            <implicitSpringDamper>1</implicitSpringDamper>
        </gazebo>


        <joint name="merlin_hinge" type="revolute">
            <origin xyz="0.62 1.5805 -1.1" rpy="1.5 0 0" />
            <parent link="${link_name}" />
            <child link="merlin_door" />
            <axis xyz="1 0 0" />
            <limit effort="1000.0" lower="-1.5" upper="0" velocity="0.25"/>
            <dynamics damping="0.55" friction="0.55"/>
        </joint>


        <link name="nanoracks_drawer">
            <inertial>
                <mass value="1.0" />
                <inertia ixx="0.857343821996639" ixy="6.2983660131078E-05" ixz="-3.19177822902163E-05" iyy="0.9174970781523" iyz="-8.19713905978223E-05" izz="0.76131215859239" />
            </inertial>
            <visual>
                <origin xyz="0 0 0" rpy="0 0 0" />
                <geometry>
                    <mesh filename="package://mantis_on_rack/meshes/plate_drawer.dae" />
                </geometry>
            </visual>
            <!-- collision>
                <origin xyz="0 0 0" rpy="0 0 0" />
                <geometry>
                    <mesh filename="package://mantis_on_rack/meshes/plate_drawer.dae" />
                </geometry>
            </collision -->
        </link>
        <gazebo reference="nanoracks_drawer">
            <material>
                Gazebo/Green
            </material>
            <implicitSpringDamper>1</implicitSpringDamper>
        </gazebo>


        <joint name="nanoracks_tray" type="prismatic">
            <!--origin xyz="0.74 1.375 -1.1" rpy="0 0 0" / -->
            <origin xyz="0.61344 1.38387 -1.13303" rpy="0 0 0" />
            <axis xyz="0 0 1"/>
            <parent link="${link_name}" />
            <child link="nanoracks_drawer" />
            <limit effort="1000.0" lower="-0.20" upper="0" velocity="0.25"/>
            <dynamics damping="0.55" friction="0.55"/>
        </joint>
    </xacro:macro>
</root>
