<?xml version="1.0" ?>
<!-- =================================================================================== -->
<!-- |    This document was autogenerated by xacro from arm_gazebo_default.urdf.xacro  | -->
<!-- |    EDITING THIS FILE BY HAND IS NOT RECOMMENDED                                 | -->
<!-- =================================================================================== -->
<robot name="defaultMantis" xmlns:xacro="http://www.ros.org/wiki/xacro">
  <link name="world"/>
  <!-- ################################# -->
  <!--        Xacro Initialization       -->
  <!-- ################################# -->
  <!-- ========PROPERTIES======= -->
  <!-- xacro:property name="pi" value="3.1415926535" / -->
  <!-- measured to edge +2mm gap -->
  <!-- In Modified DH Parameters, the d values are expressed as distances along the Z axis of the ith joint
                 But the joint offset vectors defined below are defined from the (i-1) axes. So the d values
            are not applied with consistent signage or along the same axes.
    -->
  <!-- ################################# -->
  <!-- ========MACROS======= -->
  <!-- ################################# -->
  <!--              Links                -->
  <!-- ################################# -->
  <!-- ======== Fixed Base ======== -->
  <!-- These inertial values are rough estimates -->
  <link name="base_link">
    <visual>
      <origin rpy="0 0 0" xyz="0 0 0"/>
      <geometry>
        <mesh filename="package://mantis/meshes/base.dae"/>
      </geometry>
    </visual>
    <inertial>
      <mass value="0.400"/>
      <inertia ixx="0.08000" ixy="0.001" ixz="0.001" iyy="0.05000" iyz="0.002" izz="0.06000"/>
    </inertial>
  </link>
  <link name="B1">
    <visual>
      <origin rpy="0 0 0" xyz="0 0 0"/>
      <geometry>
        <mesh filename="package://mantis/meshes/B1.dae"/>
      </geometry>
    </visual>
    <inertial>
      <mass value="0.175"/>
      <inertia ixx="0.000586" ixy="0" ixz="0" iyy="0.000579" iyz="0" izz="0.000068"/>
    </inertial>
  </link>
  <link name="B2">
    <visual>
      <origin rpy="0 0 0" xyz="0 0 0"/>
      <geometry>
        <mesh filename="package://mantis/meshes/B2.dae"/>
      </geometry>
    </visual>
    <inertial>
      <mass value="0.383"/>
      <inertia ixx="0.008240" ixy="0" ixz="0" iyy="0.000117" iyz="0" izz="0.008234"/>
    </inertial>
  </link>
  <link name="B3">
    <visual>
      <origin rpy="0 0 0" xyz="0 0 0"/>
      <geometry>
        <mesh filename="package://mantis/meshes/B3.dae"/>
      </geometry>
    </visual>
    <inertial>
      <mass value="0.320"/>
      <inertia ixx="0.000272" ixy="0" ixz="0" iyy="0.000101" iyz="0" izz="0.000303"/>
    </inertial>
  </link>
  <link name="B4">
    <visual>
      <origin rpy="0 0 0" xyz="0 0 0"/>
      <geometry>
        <mesh filename="package://mantis/meshes/B4.dae"/>
      </geometry>
    </visual>
    <inertial>
      <mass value="0.383"/>
      <inertia ixx="0.008240" ixy="0" ixz="0" iyy="0.000117" iyz="0" izz="0.008234"/>
    </inertial>
  </link>
  <link name="B5">
    <visual>
      <origin rpy="0 0 0" xyz="0 0 0"/>
      <geometry>
        <mesh filename="package://mantis/meshes/B5.dae"/>
      </geometry>
    </visual>
    <inertial>
      <mass value="0.320"/>
      <inertia ixx="0.000272" ixy="0" ixz="0" iyy="0.000101" iyz="0" izz="0.000303"/>
    </inertial>
  </link>
  <link name="B6">
    <visual>
      <origin rpy="0 0 0" xyz="0 0 0"/>
      <geometry>
        <mesh filename="package://mantis/meshes/B6.dae"/>
      </geometry>
    </visual>
    <inertial>
      <mass value="0.383"/>
      <inertia ixx="0.008240" ixy="0" ixz="0" iyy="0.000117" iyz="0" izz="0.008234"/>
    </inertial>
  </link>
  <link name="B7">
    <visual>
      <origin rpy="0 0 0" xyz="0 0 0"/>
      <geometry>
        <mesh filename="package://mantis/meshes/B7.dae"/>
      </geometry>
    </visual>
    <inertial>
      <mass value="0.320"/>
      <inertia ixx="0.000272" ixy="0" ixz="0" iyy="0.000101" iyz="0" izz="0.000303"/>
    </inertial>
  </link>
  <link name="B8">
    <visual>
      <origin rpy="0 0 0" xyz="0 0 0"/>
      <geometry>
        <mesh filename="package://mantis/meshes/B8.dae"/>
      </geometry>
    </visual>
    <inertial>
      <mass value="0.150"/>
      <inertia ixx="0.000586" ixy="0" ixz="0" iyy="0.000068" iyz="0" izz="0.000579"/>
    </inertial>
  </link>
  <link name="Palm">
    <visual>
      <origin rpy="0 0 0" xyz="0 0 0"/>
      <geometry>
        <mesh filename="package://mantis/meshes/gripper/palm.dae"/>
      </geometry>
    </visual>
    <collision>
      <origin rpy="0 0 0" xyz="0 0 0"/>
      <geometry>
        <mesh filename="package://mantis/meshes/gripper/palm.dae"/>
      </geometry>
    </collision>
    <inertial>
      <mass value="0.400"/>
      <inertia ixx="0.5000" ixy="0.000" ixz="0.00" iyy="0.5000" iyz="0.00" izz="0.6000"/>
    </inertial>
  </link>
  <link name="Proximal_L">
    <visual>
      <origin rpy="0 0 0" xyz="0 0 0"/>
      <geometry>
        <mesh filename="package://mantis/meshes/gripper/proximal_L.dae"/>
      </geometry>
    </visual>
    <collision>
      <origin rpy="0 0 0" xyz="0 0 0"/>
      <geometry>
        <mesh filename="package://mantis/meshes/gripper/proximal_L.dae"/>
      </geometry>
    </collision>
    <inertial>
      <mass value="0.010"/>
      <inertia ixx="0.0006" ixy="0.0" ixz="0.0" iyy="0.0002" iyz="0.0" izz="0.0006"/>
    </inertial>
  </link>
  <link name="Proximal_R">
    <visual>
      <origin rpy="0 0 0" xyz="0 0 0"/>
      <geometry>
        <mesh filename="package://mantis/meshes/gripper/proximal_R.dae"/>
      </geometry>
    </visual>
    <collision>
      <origin rpy="0 0 0" xyz="0 0 0"/>
      <geometry>
        <mesh filename="package://mantis/meshes/gripper/proximal_R.dae"/>
      </geometry>
    </collision>
    <inertial>
      <mass value="0.010"/>
      <inertia ixx="0.0006" ixy="0.0" ixz="0.0" iyy="0.0002" iyz="0.0" izz="0.0006"/>
    </inertial>
  </link>
  <link name="Distal_L">
    <visual>
      <origin rpy="0 0 0" xyz="0 0 0"/>
      <geometry>
        <mesh filename="package://mantis/meshes/gripper/distal_L.dae"/>
      </geometry>
    </visual>
    <collision>
      <origin rpy="0 0 0" xyz="0 0 0"/>
      <geometry>
        <mesh filename="package://mantis/meshes/gripper/distal_L.dae"/>
      </geometry>
    </collision>
    <inertial>
      <mass value="0.010"/>
      <inertia ixx="0.0006" ixy="0.0" ixz="0.0" iyy="0.0002" iyz="0.0" izz="0.0006"/>
    </inertial>
  </link>
  <link name="Distal_R">
    <visual>
      <origin rpy="0 0 0" xyz="0 0 0"/>
      <geometry>
        <mesh filename="package://mantis/meshes/gripper/distal_R.dae"/>
      </geometry>
    </visual>
    <collision>
      <origin rpy="0 0 0" xyz="0 0 0"/>
      <geometry>
        <mesh filename="package://mantis/meshes/gripper/distal_R.dae"/>
      </geometry>
    </collision>
    <inertial>
      <mass value="0.010"/>
      <inertia ixx="0.0006" ixy="0.0" ixz="0.0" iyy="0.0002" iyz="0.0" izz="0.0006"/>
    </inertial>
  </link>
  <!-- ################################# -->
  <!-- ################################# -->
  <!--             Joints                -->
  <!-- ################################# -->
  <!-- ======== Joint 0 (fixed) ========
        This joint places the arm within the global environment
        using this file's arguments env_base and origin
    -->
  <joint name="anchor" type="fixed">
    <origin rpy="0 0 0" xyz="0 0 0.01"/>
    <parent link="world"/>
    <child link="base_link"/>
  </joint>
  <joint name="J1_roll" type="continuous">
    <parent link="base_link"/>
    <child link="B1"/>
    <origin rpy="0 0 0" xyz="0 0 0.129"/>
    <axis xyz="0 0 1">
      <dynamics damping="0.25" friction="0.25"/>
    </axis>
    <limit effort="30.0" velocity="10"/>
  </joint>
  <joint name="J2_pitch" type="continuous">
    <parent link="B1"/>
    <child link="B2"/>
    <origin rpy="-1.57079632679 0 0" xyz="0 0 0"/>
    <axis xyz="0 0 1">
      <dynamics damping="0.25" friction="0.25"/>
    </axis>
    <limit effort="30.0" velocity="10"/>
  </joint>
  <joint name="J3_roll" type="continuous">
    <parent link="B2"/>
    <child link="B3"/>
    <origin rpy="1.57079632679 0 0" xyz="0 -0.29 0"/>
    <axis xyz="0 0 1">
      <dynamics damping="0.25" friction="0.25"/>
    </axis>
    <limit effort="30.0" velocity="10"/>
  </joint>
  <joint name="J4_pitch" type="continuous">
    <parent link="B3"/>
    <child link="B4"/>
    <origin rpy="-1.57079632679 0 0" xyz="0 0.056 0"/>
    <axis xyz="0 0 1">
      <dynamics damping="0.25" friction="0.25"/>
    </axis>
    <limit effort="30.0" velocity="10"/>
  </joint>
  <joint name="J5_roll" type="continuous">
    <parent link="B4"/>
    <child link="B5"/>
    <origin rpy="1.57079632679 0 0" xyz="0 -0.29 0"/>
    <axis xyz="0 0 1">
      <dynamics damping="0.25" friction="0.25"/>
    </axis>
    <limit effort="30.0" velocity="10"/>
  </joint>
  <joint name="J6_pitch" type="continuous">
    <parent link="B5"/>
    <child link="B6"/>
    <origin rpy="-1.57079632679 0 0" xyz="0 -0.056 0"/>
    <axis xyz="0 0 1">
      <dynamics damping="0.25" friction="0.25"/>
    </axis>
    <limit effort="30.0" velocity="10"/>
  </joint>
  <joint name="J7_roll" type="continuous">
    <parent link="B6"/>
    <child link="B7"/>
    <origin rpy="1.57079632679 0 0" xyz="0 -0.29 0"/>
    <axis xyz="0 0 1">
      <dynamics damping="0.25" friction="0.25"/>
    </axis>
    <limit effort="30.0" velocity="10"/>
  </joint>
  <joint name="J8_pitch" type="continuous">
    <parent link="B7"/>
    <child link="B8"/>
    <origin rpy="-1.57079632679 0 0" xyz="0 0.056 0"/>
    <axis xyz="0 0 1">
      <dynamics damping="0.25" friction="0.25"/>
    </axis>
    <limit effort="30.0" velocity="10"/>
  </joint>
  <joint name="J9_wrist" type="continuous">
    <parent link="B8"/>
    <child link="Palm"/>
    <origin rpy="1.57079632679 0 0" xyz="0 -0.067 0"/>
    <axis xyz="0 0 1">
      <dynamics damping="0.25" friction="0.25"/>
    </axis>
    <limit effort="30.0" velocity="10"/>
  </joint>
  <joint name="J1_L_wrist" type="continuous">
    <parent link="Palm"/>
    <child link="Proximal_L"/>
    <origin rpy="-1.57079632679 0 0" xyz=" 0.04334 0 0.071569"/>
    <axis xyz="0 0 1">
      <dynamics damping="0.25" friction="0.25"/>
    </axis>
    <limit effort="30.0" velocity="10"/>
  </joint>
  <joint name="J1_R_wrist" type="continuous">
    <parent link="Palm"/>
    <child link="Proximal_R"/>
    <origin rpy="-1.57079632679 0 0" xyz="-0.04334 0 0.071569"/>
    <axis xyz="0 0 1">
      <dynamics damping="0.25" friction="0.25"/>
    </axis>
    <limit effort="30.0" velocity="10"/>
  </joint>
  <joint name="J2_L_wrist" type="continuous">
    <parent link="Proximal_L"/>
    <child link="Distal_L"/>
    <origin rpy="0 0 0" xyz=" 0 -0.06789 0 "/>
    <axis xyz="0 0 1">
      <dynamics damping="0.25" friction="0.25"/>
    </axis>
    <limit effort="30.0" velocity="10"/>
  </joint>
  <joint name="J2_R_wrist" type="continuous">
    <parent link="Proximal_R"/>
    <child link="Distal_R"/>
    <origin rpy="0 0 0" xyz=" 0 -0.06789 0 "/>
    <axis xyz="0 0 1">
      <dynamics damping="0.25" friction="0.25"/>
    </axis>
    <limit effort="30.0" velocity="10"/>
  </joint>
  <!-- ################################# -->
  <!--             PLUGINS               -->
  <!-- ################################# -->
  <gazebo>
    <plugin filename="libgazebo_ros_control.so" name="gazebo_ros_control">
      <robotNamespace>/mantis</robotNamespace>
    </plugin>
  </gazebo>
  <!-- ################################# -->
  <transmission name="J1_roll_transmission">
    <type>transmission_interface/SimpleTransmission</type>
    <joint name="J1_roll">
      <hardwareInterface>EffortJointInterface</hardwareInterface>
    </joint>
    <actuator name="J1_roll_motor">
      <hardwareInterface>EffortJointInterface</hardwareInterface>
    </actuator>
  </transmission>
  <transmission name="J2_pitch_transmission">
    <type>transmission_interface/SimpleTransmission</type>
    <joint name="J2_pitch">
      <hardwareInterface>EffortJointInterface</hardwareInterface>
    </joint>
    <actuator name="J2_pitch_motor">
      <hardwareInterface>EffortJointInterface</hardwareInterface>
    </actuator>
  </transmission>
  <transmission name="J3_roll_transmission">
    <type>transmission_interface/SimpleTransmission</type>
    <joint name="J3_roll">
      <hardwareInterface>EffortJointInterface</hardwareInterface>
    </joint>
    <actuator name="J3_roll_motor">
      <hardwareInterface>EffortJointInterface</hardwareInterface>
    </actuator>
  </transmission>
  <transmission name="J4_pitch_transmission">
    <type>transmission_interface/SimpleTransmission</type>
    <joint name="J4_pitch">
      <hardwareInterface>EffortJointInterface</hardwareInterface>
    </joint>
    <actuator name="J4_pitch_motor">
      <hardwareInterface>EffortJointInterface</hardwareInterface>
    </actuator>
  </transmission>
  <transmission name="J5_roll_transmission">
    <type>transmission_interface/SimpleTransmission</type>
    <joint name="J5_roll">
      <hardwareInterface>EffortJointInterface</hardwareInterface>
    </joint>
    <actuator name="J5_roll_motor">
      <hardwareInterface>EffortJointInterface</hardwareInterface>
    </actuator>
  </transmission>
  <transmission name="J6_pitch_transmission">
    <type>transmission_interface/SimpleTransmission</type>
    <joint name="J6_pitch">
      <hardwareInterface>EffortJointInterface</hardwareInterface>
    </joint>
    <actuator name="J6_pitch_motor">
      <hardwareInterface>EffortJointInterface</hardwareInterface>
    </actuator>
  </transmission>
  <transmission name="J7_roll_transmission">
    <type>transmission_interface/SimpleTransmission</type>
    <joint name="J7_roll">
      <hardwareInterface>EffortJointInterface</hardwareInterface>
    </joint>
    <actuator name="J7_roll_motor">
      <hardwareInterface>EffortJointInterface</hardwareInterface>
    </actuator>
  </transmission>
  <transmission name="J8_pitch_transmission">
    <type>transmission_interface/SimpleTransmission</type>
    <joint name="J8_pitch">
      <hardwareInterface>EffortJointInterface</hardwareInterface>
    </joint>
    <actuator name="J8_pitch_motor">
      <hardwareInterface>EffortJointInterface</hardwareInterface>
    </actuator>
  </transmission>
  <transmission name="J9_wrist_transmission">
    <type>transmission_interface/SimpleTransmission</type>
    <joint name="J9_wrist">
      <hardwareInterface>EffortJointInterface</hardwareInterface>
    </joint>
    <actuator name="J9_wrist_motor">
      <hardwareInterface>EffortJointInterface</hardwareInterface>
    </actuator>
  </transmission>
  <transmission name="J1_L_wrist_transmission">
    <type>transmission_interface/SimpleTransmission</type>
    <joint name="J1_L_wrist">
      <hardwareInterface>EffortJointInterface</hardwareInterface>
    </joint>
    <actuator name="J1_L_wrist_motor">
      <hardwareInterface>EffortJointInterface</hardwareInterface>
    </actuator>
  </transmission>
  <transmission name="J1_R_wrist_transmission">
    <type>transmission_interface/SimpleTransmission</type>
    <joint name="J1_R_wrist">
      <hardwareInterface>EffortJointInterface</hardwareInterface>
    </joint>
    <actuator name="J1_R_wrist_motor">
      <hardwareInterface>EffortJointInterface</hardwareInterface>
    </actuator>
  </transmission>
  <!-- Friction
        Detailed description needed-->
  <!-- ################################# -->
  <!--           Materials               -->
  <!-- ################################# -->
  <gazebo reference="base_link">
    <material>
            Gazebo/Black
        </material>
    <implicitSpringDamper>1</implicitSpringDamper>
    <mu1>100000</mu1>
    <mu2>100000</mu2>
    <kp>100.0</kp>
    <kd>0.01</kd>
  </gazebo>
  <gazebo reference="B1">
    <material>
            Gazebo/DarkGrey
        </material>
    <implicitSpringDamper>1</implicitSpringDamper>
    <mu1>100000</mu1>
    <mu2>100000</mu2>
    <kp>100.0</kp>
    <kd>0.01</kd>
  </gazebo>
  <gazebo reference="B2">
    <material>
            Gazebo/Grey
        </material>
    <implicitSpringDamper>1</implicitSpringDamper>
    <mu1>100000</mu1>
    <mu2>100000</mu2>
    <kp>100.0</kp>
    <kd>0.01</kd>
  </gazebo>
  <gazebo reference="B3">
    <material>
            Gazebo/DarkGrey
        </material>
    <implicitSpringDamper>1</implicitSpringDamper>
    <mu1>100000</mu1>
    <mu2>100000</mu2>
    <kp>100.0</kp>
    <kd>0.01</kd>
  </gazebo>
  <gazebo reference="B4">
    <material>
            Gazebo/Grey
        </material>
    <implicitSpringDamper>1</implicitSpringDamper>
    <mu1>100000</mu1>
    <mu2>100000</mu2>
    <kp>100.0</kp>
    <kd>0.01</kd>
  </gazebo>
  <gazebo reference="B5">
    <material>
            Gazebo/DarkGrey
        </material>
    <implicitSpringDamper>1</implicitSpringDamper>
    <mu1>100000</mu1>
    <mu2>100000</mu2>
    <kp>100.0</kp>
    <kd>0.01</kd>
  </gazebo>
  <gazebo reference="B6">
    <material>
            Gazebo/Grey
        </material>
    <implicitSpringDamper>1</implicitSpringDamper>
    <mu1>100000</mu1>
    <mu2>100000</mu2>
    <kp>100.0</kp>
    <kd>0.01</kd>
  </gazebo>
  <gazebo reference="B7">
    <material>
            Gazebo/DarkGrey
        </material>
    <implicitSpringDamper>1</implicitSpringDamper>
    <mu1>100000</mu1>
    <mu2>100000</mu2>
    <kp>100.0</kp>
    <kd>0.01</kd>
  </gazebo>
  <gazebo reference="B8">
    <material>
            Gazebo/Grey
        </material>
    <implicitSpringDamper>1</implicitSpringDamper>
    <mu1>100000</mu1>
    <mu2>100000</mu2>
    <kp>100.0</kp>
    <kd>0.01</kd>
  </gazebo>
  <gazebo reference="Hand">
    <material>
            Gazebo/SkyBlue
        </material>
    <implicitSpringDamper>1</implicitSpringDamper>
    <mu1>100000</mu1>
    <mu2>100000</mu2>
    <kp>100.0</kp>
    <kd>0.01</kd>
  </gazebo>
  <gazebo reference="Plate">
    <material>
            Gazebo/Turquoise
        </material>
    <implicitSpringDamper>1</implicitSpringDamper>
    <mu1>100000</mu1>
    <mu2>100000</mu2>
    <kp>100.0</kp>
    <kd>0.01</kd>
  </gazebo>
  <!-- ################################# -->
</robot>

